2025-06-01 18:05:14,552 - __main__ - INFO - Telegram Bot starting...
2025-06-01 18:05:14,553 - __main__ - ERROR - Bot stopped due to error: 
2025-06-01 18:05:14,571 - __main__ - ERROR - Traceback: Traceback (most recent call last):
  File "C:\projects\telegrambot\bot.py", line 127, in <module>
    asyncio.run(main())
  File "C:\Users\harsh\Anaconda3\Lib\asyncio\runners.py", line 194, in run
    return runner.run(main)
           ^^^^^^^^^^^^^^^^
  File "C:\Users\harsh\Anaconda3\Lib\asyncio\runners.py", line 118, in run
    return self._loop.run_until_complete(task)
           ^^^^^^^^^^^^^^^^^^^^^^^^^^^^^^^^^^^
  File "C:\Users\harsh\Anaconda3\Lib\asyncio\base_events.py", line 687, in run_until_complete
    return future.result()
           ^^^^^^^^^^^^^^^
  File "C:\projects\telegrambot\bot.py", line 99, in main
    asyncio.get_event_loop().add_signal_handler(sig, signal_handler)
  File "C:\Users\harsh\Anaconda3\Lib\asyncio\events.py", line 582, in add_signal_handler
    raise NotImplementedError
NotImplementedError

2025-06-01 18:05:14,575 - __main__ - INFO - Bot shutdown complete
2025-06-01 18:06:12,968 - __main__ - INFO - Telegram Bot starting...
2025-06-01 18:06:13,089 - __main__ - INFO - Initializing application...
2025-06-01 18:06:13,693 - httpx - INFO - HTTP Request: POST https://api.telegram.org/bot8176289229:AAHWlhUIHEWbZpmKW-AwYPnTvCN4Q2td13E/getMe "HTTP/1.1 200 OK"
2025-06-01 18:06:13,696 - __main__ - INFO - Starting application...
2025-06-01 18:06:13,696 - telegram.ext.Application - INFO - Application started
2025-06-01 18:06:13,696 - __main__ - INFO - Starting polling...
2025-06-01 18:06:13,894 - httpx - INFO - HTTP Request: POST https://api.telegram.org/bot8176289229:AAHWlhUIHEWbZpmKW-AwYPnTvCN4Q2td13E/deleteWebhook "HTTP/1.1 200 OK"
2025-06-01 18:06:13,900 - __main__ - INFO - Bot is now running!
2025-06-01 18:06:14,446 - httpx - INFO - HTTP Request: POST https://api.telegram.org/bot8176289229:AAHWlhUIHEWbZpmKW-AwYPnTvCN4Q2td13E/getUpdates "HTTP/1.1 200 OK"
2025-06-01 18:06:19,013 - httpx - INFO - HTTP Request: POST https://api.openai.com/v1/completions "HTTP/1.1 200 OK"
2025-06-01 18:06:19,797 - httpx - INFO - HTTP Request: POST https://api.telegram.org/bot8176289229:AAHWlhUIHEWbZpmKW-AwYPnTvCN4Q2td13E/sendMessage "HTTP/1.1 200 OK"
2025-06-01 18:06:29,206 - httpx - INFO - HTTP Request: POST https://api.telegram.org/bot8176289229:AAHWlhUIHEWbZpmKW-AwYPnTvCN4Q2td13E/getUpdates "HTTP/1.1 200 OK"
2025-06-01 18:06:31,835 - httpx - INFO - HTTP Request: POST https://api.telegram.org/bot8176289229:AAHWlhUIHEWbZpmKW-AwYPnTvCN4Q2td13E/getUpdates "HTTP/1.1 200 OK"
2025-06-01 18:06:34,139 - httpx - INFO - HTTP Request: POST https://api.openai.com/v1/completions "HTTP/1.1 200 OK"
2025-06-01 18:06:34,968 - httpx - INFO - HTTP Request: POST https://api.telegram.org/bot8176289229:AAHWlhUIHEWbZpmKW-AwYPnTvCN4Q2td13E/sendMessage "HTTP/1.1 200 OK"
2025-06-01 18:06:44,324 - httpx - INFO - HTTP Request: POST https://api.telegram.org/bot8176289229:AAHWlhUIHEWbZpmKW-AwYPnTvCN4Q2td13E/getUpdates "HTTP/1.1 200 OK"
2025-06-01 18:06:45,897 - httpx - INFO - HTTP Request: POST https://api.telegram.org/bot8176289229:AAHWlhUIHEWbZpmKW-AwYPnTvCN4Q2td13E/getUpdates "HTTP/1.1 200 OK"
2025-06-01 18:06:49,712 - httpx - INFO - HTTP Request: POST https://api.openai.com/v1/completions "HTTP/1.1 200 OK"
2025-06-01 18:06:50,502 - httpx - INFO - HTTP Request: POST https://api.telegram.org/bot8176289229:AAHWlhUIHEWbZpmKW-AwYPnTvCN4Q2td13E/sendMessage "HTTP/1.1 200 OK"
2025-06-01 18:06:59,910 - httpx - INFO - HTTP Request: POST https://api.telegram.org/bot8176289229:AAHWlhUIHEWbZpmKW-AwYPnTvCN4Q2td13E/getUpdates "HTTP/1.1 200 OK"
2025-06-01 18:07:10,093 - httpx - INFO - HTTP Request: POST https://api.telegram.org/bot8176289229:AAHWlhUIHEWbZpmKW-AwYPnTvCN4Q2td13E/getUpdates "HTTP/1.1 200 OK"
2025-06-01 18:07:10,783 - httpx - INFO - HTTP Request: POST https://api.telegram.org/bot8176289229:AAHWlhUIHEWbZpmKW-AwYPnTvCN4Q2td13E/getUpdates "HTTP/1.1 200 OK"
2025-06-01 18:07:14,213 - httpx - INFO - HTTP Request: POST https://api.openai.com/v1/completions "HTTP/1.1 200 OK"
2025-06-01 18:07:15,123 - httpx - INFO - HTTP Request: POST https://api.telegram.org/bot8176289229:AAHWlhUIHEWbZpmKW-AwYPnTvCN4Q2td13E/sendMessage "HTTP/1.1 200 OK"
2025-06-01 18:07:24,397 - httpx - INFO - HTTP Request: POST https://api.telegram.org/bot8176289229:AAHWlhUIHEWbZpmKW-AwYPnTvCN4Q2td13E/getUpdates "HTTP/1.1 200 OK"
2025-06-01 18:07:30,264 - httpx - INFO - HTTP Request: POST https://api.telegram.org/bot8176289229:AAHWlhUIHEWbZpmKW-AwYPnTvCN4Q2td13E/getUpdates "HTTP/1.1 200 OK"
2025-06-01 18:07:31,984 - httpx - INFO - HTTP Request: POST https://api.openai.com/v1/completions "HTTP/1.1 200 OK"
2025-06-01 18:07:32,713 - httpx - INFO - HTTP Request: POST https://api.telegram.org/bot8176289229:AAHWlhUIHEWbZpmKW-AwYPnTvCN4Q2td13E/sendMessage "HTTP/1.1 200 OK"
2025-06-01 18:07:42,170 - httpx - INFO - HTTP Request: POST https://api.telegram.org/bot8176289229:AAHWlhUIHEWbZpmKW-AwYPnTvCN4Q2td13E/getUpdates "HTTP/1.1 200 OK"
2025-06-01 18:07:44,572 - __main__ - INFO - Stopping application...
2025-06-01 18:07:44,573 - telegram.ext.Application - INFO - Application is stopping. This might take a moment.
2025-06-01 18:07:44,573 - telegram.ext.Application - INFO - Application.stop() complete
2025-06-01 18:07:44,574 - __main__ - INFO - Shutting down application...
2025-06-01 18:07:44,576 - __main__ - ERROR - Bot stopped due to error: This Updater is still running!
2025-06-01 18:07:44,588 - __main__ - ERROR - Traceback: Traceback (most recent call last):
  File "C:\projects\telegrambot\bot.py", line 117, in main
    await stop.wait()
  File "C:\Users\harsh\Anaconda3\Lib\asyncio\locks.py", line 212, in wait
    await fut
asyncio.exceptions.CancelledError

During handling of the above exception, another exception occurred:

Traceback (most recent call last):
  File "C:\projects\telegrambot\bot.py", line 133, in <module>
    asyncio.run(main())
  File "C:\Users\harsh\Anaconda3\Lib\asyncio\runners.py", line 194, in run
    return runner.run(main)
           ^^^^^^^^^^^^^^^^
  File "C:\Users\harsh\Anaconda3\Lib\asyncio\runners.py", line 118, in run
    return self._loop.run_until_complete(task)
           ^^^^^^^^^^^^^^^^^^^^^^^^^^^^^^^^^^^
  File "C:\Users\harsh\Anaconda3\Lib\asyncio\base_events.py", line 687, in run_until_complete
    return future.result()
           ^^^^^^^^^^^^^^^
  File "C:\projects\telegrambot\bot.py", line 128, in main
    await application.shutdown()
  File "C:\projects\telegrambot\venv\Lib\site-packages\telegram\ext\_application.py", line 544, in shutdown
    await self.updater.shutdown()
  File "C:\projects\telegrambot\venv\Lib\site-packages\telegram\ext\_updater.py", line 196, in shutdown
    raise RuntimeError("This Updater is still running!")
RuntimeError: This Updater is still running!

2025-06-01 18:07:44,591 - __main__ - INFO - Bot shutdown complete
2025-06-01 18:07:44,799 - asyncio - ERROR - Task exception was never retrieved
future: <Task finished name='Task-35' coro=<Updater._start_polling.<locals>.polling_action_cb() done, defined at C:\projects\telegrambot\venv\Lib\site-packages\telegram\ext\_updater.py:333> exception=NetworkError('httpx.ReadError: ')>
Traceback (most recent call last):
  File "C:\projects\telegrambot\venv\Lib\site-packages\httpx\_transports\default.py", line 101, in map_httpcore_exceptions
    yield
  File "C:\projects\telegrambot\venv\Lib\site-packages\httpx\_transports\default.py", line 394, in handle_async_request
    resp = await self._pool.handle_async_request(req)
           ^^^^^^^^^^^^^^^^^^^^^^^^^^^^^^^^^^^^^^^^^^
  File "C:\projects\telegrambot\venv\Lib\site-packages\httpcore\_async\connection_pool.py", line 256, in handle_async_request
    raise exc from None
  File "C:\projects\telegrambot\venv\Lib\site-packages\httpcore\_async\connection_pool.py", line 236, in handle_async_request
    response = await connection.handle_async_request(
               ^^^^^^^^^^^^^^^^^^^^^^^^^^^^^^^^^^^^^^
  File "C:\projects\telegrambot\venv\Lib\site-packages\httpcore\_async\connection.py", line 103, in handle_async_request
    return await self._connection.handle_async_request(request)
           ^^^^^^^^^^^^^^^^^^^^^^^^^^^^^^^^^^^^^^^^^^^^^^^^^^^^
  File "C:\projects\telegrambot\venv\Lib\site-packages\httpcore\_async\http11.py", line 136, in handle_async_request
    raise exc
  File "C:\projects\telegrambot\venv\Lib\site-packages\httpcore\_async\http11.py", line 106, in handle_async_request
    ) = await self._receive_response_headers(**kwargs)
        ^^^^^^^^^^^^^^^^^^^^^^^^^^^^^^^^^^^^^^^^^^^^^^
  File "C:\projects\telegrambot\venv\Lib\site-packages\httpcore\_async\http11.py", line 177, in _receive_response_headers
    event = await self._receive_event(timeout=timeout)
            ^^^^^^^^^^^^^^^^^^^^^^^^^^^^^^^^^^^^^^^^^^
  File "C:\projects\telegrambot\venv\Lib\site-packages\httpcore\_async\http11.py", line 217, in _receive_event
    data = await self._network_stream.read(
           ^^^^^^^^^^^^^^^^^^^^^^^^^^^^^^^^
  File "C:\projects\telegrambot\venv\Lib\site-packages\httpcore\_backends\anyio.py", line 32, in read
    with map_exceptions(exc_map):
         ^^^^^^^^^^^^^^^^^^^^^^^
  File "C:\Users\harsh\Anaconda3\Lib\contextlib.py", line 158, in __exit__
    self.gen.throw(value)
  File "C:\projects\telegrambot\venv\Lib\site-packages\httpcore\_exceptions.py", line 14, in map_exceptions
    raise to_exc(exc) from exc
httpcore.ReadError

The above exception was the direct cause of the following exception:

Traceback (most recent call last):
  File "C:\projects\telegrambot\venv\Lib\site-packages\telegram\request\_httpxrequest.py", line 273, in do_request
    res = await self._client.request(
          ^^^^^^^^^^^^^^^^^^^^^^^^^^^
  File "C:\projects\telegrambot\venv\Lib\site-packages\httpx\_client.py", line 1540, in request
    return await self.send(request, auth=auth, follow_redirects=follow_redirects)
           ^^^^^^^^^^^^^^^^^^^^^^^^^^^^^^^^^^^^^^^^^^^^^^^^^^^^^^^^^^^^^^^^^^^^^^
  File "C:\projects\telegrambot\venv\Lib\site-packages\httpx\_client.py", line 1629, in send
    response = await self._send_handling_auth(
               ^^^^^^^^^^^^^^^^^^^^^^^^^^^^^^^
  File "C:\projects\telegrambot\venv\Lib\site-packages\httpx\_client.py", line 1657, in _send_handling_auth
    response = await self._send_handling_redirects(
               ^^^^^^^^^^^^^^^^^^^^^^^^^^^^^^^^^^^^
  File "C:\projects\telegrambot\venv\Lib\site-packages\httpx\_client.py", line 1694, in _send_handling_redirects
    response = await self._send_single_request(request)
               ^^^^^^^^^^^^^^^^^^^^^^^^^^^^^^^^^^^^^^^^
  File "C:\projects\telegrambot\venv\Lib\site-packages\httpx\_client.py", line 1730, in _send_single_request
    response = await transport.handle_async_request(request)
               ^^^^^^^^^^^^^^^^^^^^^^^^^^^^^^^^^^^^^^^^^^^^^
  File "C:\projects\telegrambot\venv\Lib\site-packages\httpx\_transports\default.py", line 393, in handle_async_request
    with map_httpcore_exceptions():
         ^^^^^^^^^^^^^^^^^^^^^^^^^
  File "C:\Users\harsh\Anaconda3\Lib\contextlib.py", line 158, in __exit__
    self.gen.throw(value)
  File "C:\projects\telegrambot\venv\Lib\site-packages\httpx\_transports\default.py", line 118, in map_httpcore_exceptions
    raise mapped_exc(message) from exc
httpx.ReadError

The above exception was the direct cause of the following exception:

Traceback (most recent call last):
  File "C:\projects\telegrambot\venv\Lib\site-packages\telegram\ext\_updater.py", line 335, in polling_action_cb
    updates = await self.bot.get_updates(
              ^^^^^^^^^^^^^^^^^^^^^^^^^^^
  File "C:\projects\telegrambot\venv\Lib\site-packages\telegram\ext\_extbot.py", line 669, in get_updates
    updates = await super().get_updates(
              ^^^^^^^^^^^^^^^^^^^^^^^^^^
  File "C:\projects\telegrambot\venv\Lib\site-packages\telegram\_bot.py", line 4601, in get_updates
    await self._post(
  File "C:\projects\telegrambot\venv\Lib\site-packages\telegram\_bot.py", line 697, in _post
    return await self._do_post(
           ^^^^^^^^^^^^^^^^^^^^
  File "C:\projects\telegrambot\venv\Lib\site-packages\telegram\ext\_extbot.py", line 369, in _do_post
    return await super()._do_post(
           ^^^^^^^^^^^^^^^^^^^^^^^
  File "C:\projects\telegrambot\venv\Lib\site-packages\telegram\_bot.py", line 726, in _do_post
    result = await request.post(
             ^^^^^^^^^^^^^^^^^^^
  File "C:\projects\telegrambot\venv\Lib\site-packages\telegram\request\_baserequest.py", line 197, in post
    result = await self._request_wrapper(
             ^^^^^^^^^^^^^^^^^^^^^^^^^^^^
  File "C:\projects\telegrambot\venv\Lib\site-packages\telegram\request\_baserequest.py", line 304, in _request_wrapper
    code, payload = await self.do_request(
                    ^^^^^^^^^^^^^^^^^^^^^^
  File "C:\projects\telegrambot\venv\Lib\site-packages\telegram\request\_httpxrequest.py", line 297, in do_request
    raise NetworkError(f"httpx.{err.__class__.__name__}: {err}") from err
telegram.error.NetworkError: httpx.ReadError: 
2025-06-01 18:15:05,360 - __main__ - INFO - Starting bot...
2025-06-01 18:15:06,092 - httpx - INFO - HTTP Request: POST https://api.telegram.org/bot8176289229:AAHWlhUIHEWbZpmKW-AwYPnTvCN4Q2td13E/getMe "HTTP/1.1 200 OK"
2025-06-01 18:15:06,093 - telegram.ext.Application - INFO - Application started
2025-06-01 18:15:06,310 - httpx - INFO - HTTP Request: POST https://api.telegram.org/bot8176289229:AAHWlhUIHEWbZpmKW-AwYPnTvCN4Q2td13E/deleteWebhook "HTTP/1.1 200 OK"
2025-06-01 18:15:06,312 - __main__ - INFO - Bot is running!
2025-06-01 18:15:16,766 - httpx - INFO - HTTP Request: POST https://api.telegram.org/bot8176289229:AAHWlhUIHEWbZpmKW-AwYPnTvCN4Q2td13E/getUpdates "HTTP/1.1 200 OK"
2025-06-01 18:15:17,541 - httpx - INFO - HTTP Request: POST https://api.telegram.org/bot8176289229:AAHWlhUIHEWbZpmKW-AwYPnTvCN4Q2td13E/sendChatAction "HTTP/1.1 200 OK"
2025-06-01 18:15:19,772 - httpx - INFO - HTTP Request: POST https://api.openai.com/v1/chat/completions "HTTP/1.1 200 OK"
2025-06-01 18:15:20,169 - httpx - INFO - HTTP Request: POST https://api.telegram.org/bot8176289229:AAHWlhUIHEWbZpmKW-AwYPnTvCN4Q2td13E/sendMessage "HTTP/1.1 200 OK"
2025-06-01 18:15:26,985 - httpx - INFO - HTTP Request: POST https://api.telegram.org/bot8176289229:AAHWlhUIHEWbZpmKW-AwYPnTvCN4Q2td13E/getUpdates "HTTP/1.1 200 OK"
2025-06-01 18:15:28,897 - httpx - INFO - HTTP Request: POST https://api.telegram.org/bot8176289229:AAHWlhUIHEWbZpmKW-AwYPnTvCN4Q2td13E/getUpdates "HTTP/1.1 200 OK"
2025-06-01 18:15:29,603 - httpx - INFO - HTTP Request: POST https://api.telegram.org/bot8176289229:AAHWlhUIHEWbZpmKW-AwYPnTvCN4Q2td13E/sendChatAction "HTTP/1.1 200 OK"
2025-06-01 18:15:31,403 - httpx - INFO - HTTP Request: POST https://api.openai.com/v1/chat/completions "HTTP/1.1 200 OK"
2025-06-01 18:15:31,769 - httpx - INFO - HTTP Request: POST https://api.telegram.org/bot8176289229:AAHWlhUIHEWbZpmKW-AwYPnTvCN4Q2td13E/sendMessage "HTTP/1.1 200 OK"
2025-06-01 18:15:39,113 - httpx - INFO - HTTP Request: POST https://api.telegram.org/bot8176289229:AAHWlhUIHEWbZpmKW-AwYPnTvCN4Q2td13E/getUpdates "HTTP/1.1 200 OK"
2025-06-01 18:15:39,626 - __main__ - INFO - Stopping bot...
2025-06-01 18:15:39,626 - telegram.ext.Application - INFO - Application is stopping. This might take a moment.
2025-06-01 18:15:39,628 - telegram.ext.Application - INFO - Application.stop() complete
2025-06-01 18:15:39,630 - __main__ - ERROR - Bot stopped due to error: This Updater is still running!
2025-06-01 18:15:39,651 - __main__ - ERROR - Traceback: Traceback (most recent call last):
  File "C:\projects\telegrambot\test.py", line 146, in main
    await stop.wait()
  File "C:\Users\harsh\Anaconda3\Lib\asyncio\locks.py", line 212, in wait
    await fut
asyncio.exceptions.CancelledError

During handling of the above exception, another exception occurred:

Traceback (most recent call last):
  File "C:\projects\telegrambot\test.py", line 162, in <module>
    asyncio.run(main())
  File "C:\Users\harsh\Anaconda3\Lib\asyncio\runners.py", line 194, in run
    return runner.run(main)
           ^^^^^^^^^^^^^^^^
  File "C:\Users\harsh\Anaconda3\Lib\asyncio\runners.py", line 118, in run
    return self._loop.run_until_complete(task)
           ^^^^^^^^^^^^^^^^^^^^^^^^^^^^^^^^^^^
  File "C:\Users\harsh\Anaconda3\Lib\asyncio\base_events.py", line 687, in run_until_complete
    return future.result()
           ^^^^^^^^^^^^^^^
  File "C:\projects\telegrambot\test.py", line 157, in main
    await application.shutdown()
  File "C:\projects\telegrambot\venv\Lib\site-packages\telegram\ext\_application.py", line 544, in shutdown
    await self.updater.shutdown()
  File "C:\projects\telegrambot\venv\Lib\site-packages\telegram\ext\_updater.py", line 196, in shutdown
    raise RuntimeError("This Updater is still running!")
RuntimeError: This Updater is still running!

2025-06-01 18:15:39,654 - __main__ - INFO - Bot shutdown complete
2025-06-01 18:15:39,743 - asyncio - ERROR - Task exception was never retrieved
future: <Task finished name='Task-18' coro=<Updater._start_polling.<locals>.polling_action_cb() done, defined at C:\projects\telegrambot\venv\Lib\site-packages\telegram\ext\_updater.py:333> exception=NetworkError('httpx.ReadError: ')>
Traceback (most recent call last):
  File "C:\projects\telegrambot\venv\Lib\site-packages\httpx\_transports\default.py", line 101, in map_httpcore_exceptions
    yield
  File "C:\projects\telegrambot\venv\Lib\site-packages\httpx\_transports\default.py", line 394, in handle_async_request
    resp = await self._pool.handle_async_request(req)
           ^^^^^^^^^^^^^^^^^^^^^^^^^^^^^^^^^^^^^^^^^^
  File "C:\projects\telegrambot\venv\Lib\site-packages\httpcore\_async\connection_pool.py", line 256, in handle_async_request
    raise exc from None
  File "C:\projects\telegrambot\venv\Lib\site-packages\httpcore\_async\connection_pool.py", line 236, in handle_async_request
    response = await connection.handle_async_request(
               ^^^^^^^^^^^^^^^^^^^^^^^^^^^^^^^^^^^^^^
  File "C:\projects\telegrambot\venv\Lib\site-packages\httpcore\_async\connection.py", line 103, in handle_async_request
    return await self._connection.handle_async_request(request)
           ^^^^^^^^^^^^^^^^^^^^^^^^^^^^^^^^^^^^^^^^^^^^^^^^^^^^
  File "C:\projects\telegrambot\venv\Lib\site-packages\httpcore\_async\http11.py", line 136, in handle_async_request
    raise exc
  File "C:\projects\telegrambot\venv\Lib\site-packages\httpcore\_async\http11.py", line 106, in handle_async_request
    ) = await self._receive_response_headers(**kwargs)
        ^^^^^^^^^^^^^^^^^^^^^^^^^^^^^^^^^^^^^^^^^^^^^^
  File "C:\projects\telegrambot\venv\Lib\site-packages\httpcore\_async\http11.py", line 177, in _receive_response_headers
    event = await self._receive_event(timeout=timeout)
            ^^^^^^^^^^^^^^^^^^^^^^^^^^^^^^^^^^^^^^^^^^
  File "C:\projects\telegrambot\venv\Lib\site-packages\httpcore\_async\http11.py", line 217, in _receive_event
    data = await self._network_stream.read(
           ^^^^^^^^^^^^^^^^^^^^^^^^^^^^^^^^
  File "C:\projects\telegrambot\venv\Lib\site-packages\httpcore\_backends\anyio.py", line 32, in read
    with map_exceptions(exc_map):
         ^^^^^^^^^^^^^^^^^^^^^^^
  File "C:\Users\harsh\Anaconda3\Lib\contextlib.py", line 158, in __exit__
    self.gen.throw(value)
  File "C:\projects\telegrambot\venv\Lib\site-packages\httpcore\_exceptions.py", line 14, in map_exceptions
    raise to_exc(exc) from exc
httpcore.ReadError

The above exception was the direct cause of the following exception:

Traceback (most recent call last):
  File "C:\projects\telegrambot\venv\Lib\site-packages\telegram\request\_httpxrequest.py", line 273, in do_request
    res = await self._client.request(
          ^^^^^^^^^^^^^^^^^^^^^^^^^^^
  File "C:\projects\telegrambot\venv\Lib\site-packages\httpx\_client.py", line 1540, in request
    return await self.send(request, auth=auth, follow_redirects=follow_redirects)
           ^^^^^^^^^^^^^^^^^^^^^^^^^^^^^^^^^^^^^^^^^^^^^^^^^^^^^^^^^^^^^^^^^^^^^^
  File "C:\projects\telegrambot\venv\Lib\site-packages\httpx\_client.py", line 1629, in send
    response = await self._send_handling_auth(
               ^^^^^^^^^^^^^^^^^^^^^^^^^^^^^^^
  File "C:\projects\telegrambot\venv\Lib\site-packages\httpx\_client.py", line 1657, in _send_handling_auth
    response = await self._send_handling_redirects(
               ^^^^^^^^^^^^^^^^^^^^^^^^^^^^^^^^^^^^
  File "C:\projects\telegrambot\venv\Lib\site-packages\httpx\_client.py", line 1694, in _send_handling_redirects
    response = await self._send_single_request(request)
               ^^^^^^^^^^^^^^^^^^^^^^^^^^^^^^^^^^^^^^^^
  File "C:\projects\telegrambot\venv\Lib\site-packages\httpx\_client.py", line 1730, in _send_single_request
    response = await transport.handle_async_request(request)
               ^^^^^^^^^^^^^^^^^^^^^^^^^^^^^^^^^^^^^^^^^^^^^
  File "C:\projects\telegrambot\venv\Lib\site-packages\httpx\_transports\default.py", line 393, in handle_async_request
    with map_httpcore_exceptions():
         ^^^^^^^^^^^^^^^^^^^^^^^^^
  File "C:\Users\harsh\Anaconda3\Lib\contextlib.py", line 158, in __exit__
    self.gen.throw(value)
  File "C:\projects\telegrambot\venv\Lib\site-packages\httpx\_transports\default.py", line 118, in map_httpcore_exceptions
    raise mapped_exc(message) from exc
httpx.ReadError

The above exception was the direct cause of the following exception:

Traceback (most recent call last):
  File "C:\projects\telegrambot\venv\Lib\site-packages\telegram\ext\_updater.py", line 335, in polling_action_cb
    updates = await self.bot.get_updates(
              ^^^^^^^^^^^^^^^^^^^^^^^^^^^
  File "C:\projects\telegrambot\venv\Lib\site-packages\telegram\ext\_extbot.py", line 669, in get_updates
    updates = await super().get_updates(
              ^^^^^^^^^^^^^^^^^^^^^^^^^^
  File "C:\projects\telegrambot\venv\Lib\site-packages\telegram\_bot.py", line 4601, in get_updates
    await self._post(
  File "C:\projects\telegrambot\venv\Lib\site-packages\telegram\_bot.py", line 697, in _post
    return await self._do_post(
           ^^^^^^^^^^^^^^^^^^^^
  File "C:\projects\telegrambot\venv\Lib\site-packages\telegram\ext\_extbot.py", line 369, in _do_post
    return await super()._do_post(
           ^^^^^^^^^^^^^^^^^^^^^^^
  File "C:\projects\telegrambot\venv\Lib\site-packages\telegram\_bot.py", line 726, in _do_post
    result = await request.post(
             ^^^^^^^^^^^^^^^^^^^
  File "C:\projects\telegrambot\venv\Lib\site-packages\telegram\request\_baserequest.py", line 197, in post
    result = await self._request_wrapper(
             ^^^^^^^^^^^^^^^^^^^^^^^^^^^^
  File "C:\projects\telegrambot\venv\Lib\site-packages\telegram\request\_baserequest.py", line 304, in _request_wrapper
    code, payload = await self.do_request(
                    ^^^^^^^^^^^^^^^^^^^^^^
  File "C:\projects\telegrambot\venv\Lib\site-packages\telegram\request\_httpxrequest.py", line 297, in do_request
    raise NetworkError(f"httpx.{err.__class__.__name__}: {err}") from err
telegram.error.NetworkError: httpx.ReadError: 
2025-06-01 18:21:32,870 - __main__ - INFO - Telegram Bot starting...
2025-06-01 18:21:33,006 - __main__ - INFO - Initializing application...
2025-06-01 18:21:33,604 - httpx - INFO - HTTP Request: POST https://api.telegram.org/bot8176289229:AAHWlhUIHEWbZpmKW-AwYPnTvCN4Q2td13E/getMe "HTTP/1.1 200 OK"
2025-06-01 18:21:33,605 - __main__ - INFO - Starting application...
2025-06-01 18:21:33,606 - telegram.ext.Application - INFO - Application started
2025-06-01 18:21:33,606 - __main__ - INFO - Starting polling...
2025-06-01 18:21:33,788 - httpx - INFO - HTTP Request: POST https://api.telegram.org/bot8176289229:AAHWlhUIHEWbZpmKW-AwYPnTvCN4Q2td13E/deleteWebhook "HTTP/1.1 200 OK"
2025-06-01 18:21:33,790 - __main__ - INFO - Bot is now running!
2025-06-01 18:21:34,403 - httpx - INFO - HTTP Request: POST https://api.telegram.org/bot8176289229:AAHWlhUIHEWbZpmKW-AwYPnTvCN4Q2td13E/getUpdates "HTTP/1.1 200 OK"
2025-06-01 18:21:34,798 - httpx - INFO - HTTP Request: POST https://api.telegram.org/bot8176289229:AAHWlhUIHEWbZpmKW-AwYPnTvCN4Q2td13E/sendMessage "HTTP/1.1 200 OK"
2025-06-01 18:21:44,608 - httpx - INFO - HTTP Request: POST https://api.telegram.org/bot8176289229:AAHWlhUIHEWbZpmKW-AwYPnTvCN4Q2td13E/getUpdates "HTTP/1.1 200 OK"
2025-06-01 18:21:54,815 - httpx - INFO - HTTP Request: POST https://api.telegram.org/bot8176289229:AAHWlhUIHEWbZpmKW-AwYPnTvCN4Q2td13E/getUpdates "HTTP/1.1 200 OK"
2025-06-01 18:22:05,021 - httpx - INFO - HTTP Request: POST https://api.telegram.org/bot8176289229:AAHWlhUIHEWbZpmKW-AwYPnTvCN4Q2td13E/getUpdates "HTTP/1.1 200 OK"
2025-06-01 18:22:15,240 - httpx - INFO - HTTP Request: POST https://api.telegram.org/bot8176289229:AAHWlhUIHEWbZpmKW-AwYPnTvCN4Q2td13E/getUpdates "HTTP/1.1 200 OK"
2025-06-01 18:22:25,456 - httpx - INFO - HTTP Request: POST https://api.telegram.org/bot8176289229:AAHWlhUIHEWbZpmKW-AwYPnTvCN4Q2td13E/getUpdates "HTTP/1.1 200 OK"
2025-06-01 18:22:35,668 - httpx - INFO - HTTP Request: POST https://api.telegram.org/bot8176289229:AAHWlhUIHEWbZpmKW-AwYPnTvCN4Q2td13E/getUpdates "HTTP/1.1 200 OK"
2025-06-01 18:22:45,152 - httpx - INFO - HTTP Request: POST https://api.telegram.org/bot8176289229:AAHWlhUIHEWbZpmKW-AwYPnTvCN4Q2td13E/getUpdates "HTTP/1.1 200 OK"
2025-06-01 18:22:45,995 - httpx - INFO - HTTP Request: POST https://api.telegram.org/bot8176289229:AAHWlhUIHEWbZpmKW-AwYPnTvCN4Q2td13E/sendMessage "HTTP/1.1 200 OK"
2025-06-01 18:22:55,362 - httpx - INFO - HTTP Request: POST https://api.telegram.org/bot8176289229:AAHWlhUIHEWbZpmKW-AwYPnTvCN4Q2td13E/getUpdates "HTTP/1.1 200 OK"
2025-06-01 18:23:05,567 - httpx - INFO - HTTP Request: POST https://api.telegram.org/bot8176289229:AAHWlhUIHEWbZpmKW-AwYPnTvCN4Q2td13E/getUpdates "HTTP/1.1 200 OK"
2025-06-01 18:23:15,775 - httpx - INFO - HTTP Request: POST https://api.telegram.org/bot8176289229:AAHWlhUIHEWbZpmKW-AwYPnTvCN4Q2td13E/getUpdates "HTTP/1.1 200 OK"
2025-06-01 18:23:25,980 - httpx - INFO - HTTP Request: POST https://api.telegram.org/bot8176289229:AAHWlhUIHEWbZpmKW-AwYPnTvCN4Q2td13E/getUpdates "HTTP/1.1 200 OK"
2025-06-01 18:23:36,185 - httpx - INFO - HTTP Request: POST https://api.telegram.org/bot8176289229:AAHWlhUIHEWbZpmKW-AwYPnTvCN4Q2td13E/getUpdates "HTTP/1.1 200 OK"
2025-06-01 18:23:46,394 - httpx - INFO - HTTP Request: POST https://api.telegram.org/bot8176289229:AAHWlhUIHEWbZpmKW-AwYPnTvCN4Q2td13E/getUpdates "HTTP/1.1 200 OK"
2025-06-01 18:23:56,603 - httpx - INFO - HTTP Request: POST https://api.telegram.org/bot8176289229:AAHWlhUIHEWbZpmKW-AwYPnTvCN4Q2td13E/getUpdates "HTTP/1.1 200 OK"
2025-06-01 18:24:06,808 - httpx - INFO - HTTP Request: POST https://api.telegram.org/bot8176289229:AAHWlhUIHEWbZpmKW-AwYPnTvCN4Q2td13E/getUpdates "HTTP/1.1 200 OK"
2025-06-01 18:24:17,018 - httpx - INFO - HTTP Request: POST https://api.telegram.org/bot8176289229:AAHWlhUIHEWbZpmKW-AwYPnTvCN4Q2td13E/getUpdates "HTTP/1.1 200 OK"
2025-06-01 18:24:27,223 - httpx - INFO - HTTP Request: POST https://api.telegram.org/bot8176289229:AAHWlhUIHEWbZpmKW-AwYPnTvCN4Q2td13E/getUpdates "HTTP/1.1 200 OK"
2025-06-01 18:24:37,434 - httpx - INFO - HTTP Request: POST https://api.telegram.org/bot8176289229:AAHWlhUIHEWbZpmKW-AwYPnTvCN4Q2td13E/getUpdates "HTTP/1.1 200 OK"
2025-06-01 18:24:47,644 - httpx - INFO - HTTP Request: POST https://api.telegram.org/bot8176289229:AAHWlhUIHEWbZpmKW-AwYPnTvCN4Q2td13E/getUpdates "HTTP/1.1 200 OK"
2025-06-01 18:24:57,850 - httpx - INFO - HTTP Request: POST https://api.telegram.org/bot8176289229:AAHWlhUIHEWbZpmKW-AwYPnTvCN4Q2td13E/getUpdates "HTTP/1.1 200 OK"
2025-06-01 18:25:08,056 - httpx - INFO - HTTP Request: POST https://api.telegram.org/bot8176289229:AAHWlhUIHEWbZpmKW-AwYPnTvCN4Q2td13E/getUpdates "HTTP/1.1 200 OK"
2025-06-01 18:25:18,271 - httpx - INFO - HTTP Request: POST https://api.telegram.org/bot8176289229:AAHWlhUIHEWbZpmKW-AwYPnTvCN4Q2td13E/getUpdates "HTTP/1.1 200 OK"
2025-06-01 18:25:28,481 - httpx - INFO - HTTP Request: POST https://api.telegram.org/bot8176289229:AAHWlhUIHEWbZpmKW-AwYPnTvCN4Q2td13E/getUpdates "HTTP/1.1 200 OK"
2025-06-01 18:25:38,714 - httpx - INFO - HTTP Request: POST https://api.telegram.org/bot8176289229:AAHWlhUIHEWbZpmKW-AwYPnTvCN4Q2td13E/getUpdates "HTTP/1.1 200 OK"
2025-06-01 18:25:48,939 - httpx - INFO - HTTP Request: POST https://api.telegram.org/bot8176289229:AAHWlhUIHEWbZpmKW-AwYPnTvCN4Q2td13E/getUpdates "HTTP/1.1 200 OK"
2025-06-01 18:25:59,146 - httpx - INFO - HTTP Request: POST https://api.telegram.org/bot8176289229:AAHWlhUIHEWbZpmKW-AwYPnTvCN4Q2td13E/getUpdates "HTTP/1.1 200 OK"
2025-06-01 18:26:09,352 - httpx - INFO - HTTP Request: POST https://api.telegram.org/bot8176289229:AAHWlhUIHEWbZpmKW-AwYPnTvCN4Q2td13E/getUpdates "HTTP/1.1 200 OK"
2025-06-01 18:26:19,560 - httpx - INFO - HTTP Request: POST https://api.telegram.org/bot8176289229:AAHWlhUIHEWbZpmKW-AwYPnTvCN4Q2td13E/getUpdates "HTTP/1.1 200 OK"
2025-06-01 18:26:29,769 - httpx - INFO - HTTP Request: POST https://api.telegram.org/bot8176289229:AAHWlhUIHEWbZpmKW-AwYPnTvCN4Q2td13E/getUpdates "HTTP/1.1 200 OK"
2025-06-01 18:26:39,979 - httpx - INFO - HTTP Request: POST https://api.telegram.org/bot8176289229:AAHWlhUIHEWbZpmKW-AwYPnTvCN4Q2td13E/getUpdates "HTTP/1.1 200 OK"
2025-06-01 18:26:50,190 - httpx - INFO - HTTP Request: POST https://api.telegram.org/bot8176289229:AAHWlhUIHEWbZpmKW-AwYPnTvCN4Q2td13E/getUpdates "HTTP/1.1 200 OK"
2025-06-01 18:27:00,397 - httpx - INFO - HTTP Request: POST https://api.telegram.org/bot8176289229:AAHWlhUIHEWbZpmKW-AwYPnTvCN4Q2td13E/getUpdates "HTTP/1.1 200 OK"
2025-06-01 18:27:10,605 - httpx - INFO - HTTP Request: POST https://api.telegram.org/bot8176289229:AAHWlhUIHEWbZpmKW-AwYPnTvCN4Q2td13E/getUpdates "HTTP/1.1 200 OK"
2025-06-01 18:27:20,829 - httpx - INFO - HTTP Request: POST https://api.telegram.org/bot8176289229:AAHWlhUIHEWbZpmKW-AwYPnTvCN4Q2td13E/getUpdates "HTTP/1.1 200 OK"
2025-06-01 18:27:31,044 - httpx - INFO - HTTP Request: POST https://api.telegram.org/bot8176289229:AAHWlhUIHEWbZpmKW-AwYPnTvCN4Q2td13E/getUpdates "HTTP/1.1 200 OK"
2025-06-01 18:27:41,253 - httpx - INFO - HTTP Request: POST https://api.telegram.org/bot8176289229:AAHWlhUIHEWbZpmKW-AwYPnTvCN4Q2td13E/getUpdates "HTTP/1.1 200 OK"
2025-06-01 18:27:51,461 - httpx - INFO - HTTP Request: POST https://api.telegram.org/bot8176289229:AAHWlhUIHEWbZpmKW-AwYPnTvCN4Q2td13E/getUpdates "HTTP/1.1 200 OK"
2025-06-01 18:28:01,677 - httpx - INFO - HTTP Request: POST https://api.telegram.org/bot8176289229:AAHWlhUIHEWbZpmKW-AwYPnTvCN4Q2td13E/getUpdates "HTTP/1.1 200 OK"
2025-06-01 18:28:12,001 - httpx - INFO - HTTP Request: POST https://api.telegram.org/bot8176289229:AAHWlhUIHEWbZpmKW-AwYPnTvCN4Q2td13E/getUpdates "HTTP/1.1 200 OK"
2025-06-01 18:28:22,209 - httpx - INFO - HTTP Request: POST https://api.telegram.org/bot8176289229:AAHWlhUIHEWbZpmKW-AwYPnTvCN4Q2td13E/getUpdates "HTTP/1.1 200 OK"
2025-06-01 18:28:32,416 - httpx - INFO - HTTP Request: POST https://api.telegram.org/bot8176289229:AAHWlhUIHEWbZpmKW-AwYPnTvCN4Q2td13E/getUpdates "HTTP/1.1 200 OK"
2025-06-01 18:28:42,624 - httpx - INFO - HTTP Request: POST https://api.telegram.org/bot8176289229:AAHWlhUIHEWbZpmKW-AwYPnTvCN4Q2td13E/getUpdates "HTTP/1.1 200 OK"
2025-06-01 18:28:52,837 - httpx - INFO - HTTP Request: POST https://api.telegram.org/bot8176289229:AAHWlhUIHEWbZpmKW-AwYPnTvCN4Q2td13E/getUpdates "HTTP/1.1 200 OK"
2025-06-01 18:29:03,047 - httpx - INFO - HTTP Request: POST https://api.telegram.org/bot8176289229:AAHWlhUIHEWbZpmKW-AwYPnTvCN4Q2td13E/getUpdates "HTTP/1.1 200 OK"
2025-06-01 18:29:13,256 - httpx - INFO - HTTP Request: POST https://api.telegram.org/bot8176289229:AAHWlhUIHEWbZpmKW-AwYPnTvCN4Q2td13E/getUpdates "HTTP/1.1 200 OK"
2025-06-01 18:29:23,463 - httpx - INFO - HTTP Request: POST https://api.telegram.org/bot8176289229:AAHWlhUIHEWbZpmKW-AwYPnTvCN4Q2td13E/getUpdates "HTTP/1.1 200 OK"
2025-06-01 18:29:29,946 - __main__ - INFO - Stopping application...
2025-06-01 18:29:29,946 - telegram.ext.Application - INFO - Application is stopping. This might take a moment.
2025-06-01 18:29:29,946 - telegram.ext.Application - INFO - Application.stop() complete
2025-06-01 18:29:29,947 - __main__ - INFO - Shutting down application...
2025-06-01 18:29:29,949 - __main__ - ERROR - Bot stopped due to error: This Updater is still running!
2025-06-01 18:29:29,954 - __main__ - ERROR - Traceback: Traceback (most recent call last):
  File "C:\projects\telegrambot\bot.py", line 117, in main
    await stop.wait()
  File "C:\Users\harsh\Anaconda3\Lib\asyncio\locks.py", line 212, in wait
    await fut
asyncio.exceptions.CancelledError

During handling of the above exception, another exception occurred:

Traceback (most recent call last):
  File "C:\projects\telegrambot\bot.py", line 133, in <module>
    asyncio.run(main())
  File "C:\Users\harsh\Anaconda3\Lib\asyncio\runners.py", line 194, in run
    return runner.run(main)
           ^^^^^^^^^^^^^^^^
  File "C:\Users\harsh\Anaconda3\Lib\asyncio\runners.py", line 118, in run
    return self._loop.run_until_complete(task)
           ^^^^^^^^^^^^^^^^^^^^^^^^^^^^^^^^^^^
  File "C:\Users\harsh\Anaconda3\Lib\asyncio\base_events.py", line 687, in run_until_complete
    return future.result()
           ^^^^^^^^^^^^^^^
  File "C:\projects\telegrambot\bot.py", line 128, in main
    await application.shutdown()
  File "C:\projects\telegrambot\venv\Lib\site-packages\telegram\ext\_application.py", line 544, in shutdown
    await self.updater.shutdown()
  File "C:\projects\telegrambot\venv\Lib\site-packages\telegram\ext\_updater.py", line 196, in shutdown
    raise RuntimeError("This Updater is still running!")
RuntimeError: This Updater is still running!

2025-06-01 18:29:29,956 - __main__ - INFO - Bot shutdown complete
2025-06-01 18:29:30,013 - asyncio - ERROR - Task exception was never retrieved
future: <Task finished name='Task-103' coro=<Updater._start_polling.<locals>.polling_action_cb() done, defined at C:\projects\telegrambot\venv\Lib\site-packages\telegram\ext\_updater.py:333> exception=NetworkError('httpx.ReadError: ')>
Traceback (most recent call last):
  File "C:\projects\telegrambot\venv\Lib\site-packages\httpx\_transports\default.py", line 101, in map_httpcore_exceptions
    yield
  File "C:\projects\telegrambot\venv\Lib\site-packages\httpx\_transports\default.py", line 394, in handle_async_request
    resp = await self._pool.handle_async_request(req)
           ^^^^^^^^^^^^^^^^^^^^^^^^^^^^^^^^^^^^^^^^^^
  File "C:\projects\telegrambot\venv\Lib\site-packages\httpcore\_async\connection_pool.py", line 256, in handle_async_request
    raise exc from None
  File "C:\projects\telegrambot\venv\Lib\site-packages\httpcore\_async\connection_pool.py", line 236, in handle_async_request
    response = await connection.handle_async_request(
               ^^^^^^^^^^^^^^^^^^^^^^^^^^^^^^^^^^^^^^
  File "C:\projects\telegrambot\venv\Lib\site-packages\httpcore\_async\connection.py", line 103, in handle_async_request
    return await self._connection.handle_async_request(request)
           ^^^^^^^^^^^^^^^^^^^^^^^^^^^^^^^^^^^^^^^^^^^^^^^^^^^^
  File "C:\projects\telegrambot\venv\Lib\site-packages\httpcore\_async\http11.py", line 136, in handle_async_request
    raise exc
  File "C:\projects\telegrambot\venv\Lib\site-packages\httpcore\_async\http11.py", line 106, in handle_async_request
    ) = await self._receive_response_headers(**kwargs)
        ^^^^^^^^^^^^^^^^^^^^^^^^^^^^^^^^^^^^^^^^^^^^^^
  File "C:\projects\telegrambot\venv\Lib\site-packages\httpcore\_async\http11.py", line 177, in _receive_response_headers
    event = await self._receive_event(timeout=timeout)
            ^^^^^^^^^^^^^^^^^^^^^^^^^^^^^^^^^^^^^^^^^^
  File "C:\projects\telegrambot\venv\Lib\site-packages\httpcore\_async\http11.py", line 217, in _receive_event
    data = await self._network_stream.read(
           ^^^^^^^^^^^^^^^^^^^^^^^^^^^^^^^^
  File "C:\projects\telegrambot\venv\Lib\site-packages\httpcore\_backends\anyio.py", line 32, in read
    with map_exceptions(exc_map):
         ^^^^^^^^^^^^^^^^^^^^^^^
  File "C:\Users\harsh\Anaconda3\Lib\contextlib.py", line 158, in __exit__
    self.gen.throw(value)
  File "C:\projects\telegrambot\venv\Lib\site-packages\httpcore\_exceptions.py", line 14, in map_exceptions
    raise to_exc(exc) from exc
httpcore.ReadError

The above exception was the direct cause of the following exception:

Traceback (most recent call last):
  File "C:\projects\telegrambot\venv\Lib\site-packages\telegram\request\_httpxrequest.py", line 273, in do_request
    res = await self._client.request(
          ^^^^^^^^^^^^^^^^^^^^^^^^^^^
  File "C:\projects\telegrambot\venv\Lib\site-packages\httpx\_client.py", line 1540, in request
    return await self.send(request, auth=auth, follow_redirects=follow_redirects)
           ^^^^^^^^^^^^^^^^^^^^^^^^^^^^^^^^^^^^^^^^^^^^^^^^^^^^^^^^^^^^^^^^^^^^^^
  File "C:\projects\telegrambot\venv\Lib\site-packages\httpx\_client.py", line 1629, in send
    response = await self._send_handling_auth(
               ^^^^^^^^^^^^^^^^^^^^^^^^^^^^^^^
  File "C:\projects\telegrambot\venv\Lib\site-packages\httpx\_client.py", line 1657, in _send_handling_auth
    response = await self._send_handling_redirects(
               ^^^^^^^^^^^^^^^^^^^^^^^^^^^^^^^^^^^^
  File "C:\projects\telegrambot\venv\Lib\site-packages\httpx\_client.py", line 1694, in _send_handling_redirects
    response = await self._send_single_request(request)
               ^^^^^^^^^^^^^^^^^^^^^^^^^^^^^^^^^^^^^^^^
  File "C:\projects\telegrambot\venv\Lib\site-packages\httpx\_client.py", line 1730, in _send_single_request
    response = await transport.handle_async_request(request)
               ^^^^^^^^^^^^^^^^^^^^^^^^^^^^^^^^^^^^^^^^^^^^^
  File "C:\projects\telegrambot\venv\Lib\site-packages\httpx\_transports\default.py", line 393, in handle_async_request
    with map_httpcore_exceptions():
         ^^^^^^^^^^^^^^^^^^^^^^^^^
  File "C:\Users\harsh\Anaconda3\Lib\contextlib.py", line 158, in __exit__
    self.gen.throw(value)
  File "C:\projects\telegrambot\venv\Lib\site-packages\httpx\_transports\default.py", line 118, in map_httpcore_exceptions
    raise mapped_exc(message) from exc
httpx.ReadError

The above exception was the direct cause of the following exception:

Traceback (most recent call last):
  File "C:\projects\telegrambot\venv\Lib\site-packages\telegram\ext\_updater.py", line 335, in polling_action_cb
    updates = await self.bot.get_updates(
              ^^^^^^^^^^^^^^^^^^^^^^^^^^^
  File "C:\projects\telegrambot\venv\Lib\site-packages\telegram\ext\_extbot.py", line 669, in get_updates
    updates = await super().get_updates(
              ^^^^^^^^^^^^^^^^^^^^^^^^^^
  File "C:\projects\telegrambot\venv\Lib\site-packages\telegram\_bot.py", line 4601, in get_updates
    await self._post(
  File "C:\projects\telegrambot\venv\Lib\site-packages\telegram\_bot.py", line 697, in _post
    return await self._do_post(
           ^^^^^^^^^^^^^^^^^^^^
  File "C:\projects\telegrambot\venv\Lib\site-packages\telegram\ext\_extbot.py", line 369, in _do_post
    return await super()._do_post(
           ^^^^^^^^^^^^^^^^^^^^^^^
  File "C:\projects\telegrambot\venv\Lib\site-packages\telegram\_bot.py", line 726, in _do_post
    result = await request.post(
             ^^^^^^^^^^^^^^^^^^^
  File "C:\projects\telegrambot\venv\Lib\site-packages\telegram\request\_baserequest.py", line 197, in post
    result = await self._request_wrapper(
             ^^^^^^^^^^^^^^^^^^^^^^^^^^^^
  File "C:\projects\telegrambot\venv\Lib\site-packages\telegram\request\_baserequest.py", line 304, in _request_wrapper
    code, payload = await self.do_request(
                    ^^^^^^^^^^^^^^^^^^^^^^
  File "C:\projects\telegrambot\venv\Lib\site-packages\telegram\request\_httpxrequest.py", line 297, in do_request
    raise NetworkError(f"httpx.{err.__class__.__name__}: {err}") from err
telegram.error.NetworkError: httpx.ReadError: 
